<!-- description of the CamBot robot, a robotics project for the UVic-UCC master in robotics first term -->
<robot name = "cambot">

	<!-- BASE-FOOTPRINT -->
	<!-- base_footprint is a fictitious link(frame) that is on the ground right below base_link origin, navigation stack depends on this frame -->
	<link name = "base_footprint"/>

	<joint name = "base_footprint_joint" type = "fixed">
		<parent link = "base_footprint"/>
		<child link = "base_link"/>
		<origin xyz = "0 0 0" rpy = "0 0 0"/>
	</joint>

	<!-- BASE-LINK -->
    <!--Actual body/chassis of the robot-->
	<link name = "base_link">
		<visual>
			<origin xyz = "0 0 0.12" rpy = "1.57 0 3.14"/>
			<geometry>
				<mesh filename = "package://cambot_description/meshes/cambot_base.stl"/>
			</geometry>
			<material name = "cambot/orange">
				<color rgba = "1.0 0.5 0.0 1.0"/>
			</material>
		</visual>
		<collision>
      		<origin xyz = "0 0 0.12" rpy = "1.57 0 3.14"/>
      		<geometry>
        		<mesh filename = "package://cambot_description/meshes/cambot_base_collision.stl" scale="0.01 0.01 0.01"/>
      		</geometry>
    	</collision>
		<inertial>
      		<origin rpy = "0 0 0" xyz = "-8.640e-3 236.599e-3 0.443e-3"/>
      		<mass value = "0.216"/>
      		<inertia ixx = "0.016258"
               ixy = "0.000432"
               ixz="-0.000049"
               iyy="0.019275"
               iyz="0.000048"
               izz="0.016834"/>
    	</inertial>
	</link>

	<joint name = "base_to_right_wheel" type = "continuous">
		<parent link = "base_link"/>
		<child link = "right_wheel_link"/>
		<origin xyz = "0.21 -0.50 0.28" rpy = "1.57 0 0"/>
		<axis xyz = "0 0 1"/>
	</joint>

	<joint name = "base_to_left_wheel" type = "continuous">
		<parent link = "base_link"/>
		<child link = "left_wheel_link"/>
		<origin xyz = "0.21 0.50 0.28" rpy = "-1.57 0 0"/>
		<axis xyz = "0 0 1"/>
	</joint>

	<joint name = "base_to_servo" type = "fixed">
		<parent link = "base_link" />
		<child link = "servo_link" />
		<origin xyz = "0.2 -0.21 1.035" rpy = "-1.57 0 0"/>
	</joint>	

	<!-- WHEEL-LINKS -->
    <!--Actual wheels of the robot-->
	<link name = "left_wheel_link">
		<visual>
			<origin xyz = "0 0 0.05" rpy = "0 -1.57 0" />
			<geometry>
				<mesh filename = "package://cambot_description/meshes/cambot_wheel.stl" />
			</geometry>
			<material name = "cambot/red">
				<color rgba = "1.0 0.0 0.0 1.0" />
			</material>
		</visual>
		<collision>
      		<origin xyz = "0 0 0.05" rpy = "0 -1.57 0" />
      		<geometry>
        		<mesh filename = "package://cambot_description/meshes/cambot_wheel_collision.stl" scale="0.01 0.01 0.01"/>
      		</geometry>
    	</collision>
		<inertial>
      		<origin rpy = "0 0 0" xyz = "-30.036e-3 0 0"/>
      		<mass value = "0.01311625"/>
      		<inertia ixx = "0.000481"
               ixy = "0.000000"
               ixz="0.000000"
               iyy="0.000244"
               iyz="0.000000"
               izz="0.000244"/>
    	</inertial>
	</link>

	<link name = "right_wheel_link">
		<visual>
			<origin xyz = "0 0 0.05" rpy = "0 -1.57 0" />
			<geometry>
				<mesh filename = "package://cambot_description/meshes/cambot_wheel.stl" />
			</geometry>
			<material name = "cambot/red">
				<color rgba = "1.0 0.0 0.0 1.0" />
			</material>
		</visual>
		<collision>
      		<origin xyz = "0 0 0.05" rpy = "0 -1.57 0" />
      		<geometry>
        		<mesh filename = "package://cambot_description/meshes/cambot_wheel_collision.stl" scale="0.01 0.01 0.01"/>
      		</geometry>
    	</collision>
		<inertial>
      		<origin rpy = "0 0 0" xyz = "-30.036e-3 0 0"/>
      		<mass value = "0.01311625"/>
      		<inertia ixx = "0.000481"
               ixy = "0.000000"
               ixz="0.000000"
               iyy="0.000244"
               iyz="0.000000"
               izz="0.000244"/>
    	</inertial>
	</link>

	<!-- SERVO-LINK -->
    <!--Actual servo of the robot responsible of the movement of the camera-->
	<link name = "servo_link">
		<visual>
			<origin xyz = "0 0 0" rpy = "0 0 3.14" />
			<geometry>
				<mesh filename = "package://cambot_description/meshes/cambot_servo.stl" />
			</geometry>
			<material name = "cambot/black">
				<color rgba = "0.0 0.0 0.0 1.0" />
			</material>
		</visual>
		<collision>
      		<origin xyz = "0 0 0" rpy = "0 0 3.14" />
      		<geometry>
        		<mesh filename = "package://cambot_description/meshes/cambot_servo_collision.stl" scale="0.01 0.01 0.01"/>
      		</geometry>
    	</collision>
		<inertial>
      		<origin rpy = "0 0 0" xyz = "105.286-3 -0.010e-3 -208.732e-3"/>
      		<mass value = "0.05686125"/>
      		<inertia ixx = "0.001002"
               ixy = "0.000000"
               ixz="0.000013"
               iyy="0.001521"
               iyz="0.000000"
               izz="0.001247"/>
    	</inertial>
	</link>

	<joint name = "servo_to_camera_support" type = "revolute">
		<limit effort="10.0" lower="-0.4" upper="0.4" velocity="0.5"/>
		<parent link = "servo_link" />
		<child link = "camera_support_link" />
		<origin xyz = "0 0 0" rpy = "0 0 0" />
		<axis xyz = "0 0 1" />
	</joint>

	<!-- CAMERA-SUPPORT-LINK -->
	<!-- Actual camera support coupled to the servo -->
	<link name = "camera_support_link">
		<visual>
			<origin xyz = "0 0 0" rpy = "0 -1.57 3.14" />
			<geometry>
				<mesh filename = "package://cambot_description/meshes/cambot_camera_support.stl" />
			</geometry>
			<material name = "cambot/blue">
				<color rgba = "0.0 0.0 255.0 1.0" />
			</material>
		</visual>
		<collision>
      		<origin xyz = "0 0 0" rpy = "0 -1.57 3.14" />
      		<geometry>
        		<mesh filename = "package://cambot_description/meshes/cambot_camera_support_collision.stl" scale="0.01 0.01 0.01"/>
      		</geometry>
    	</collision>
		<inertial>
      		<origin rpy = "0 0 0" xyz = "296.718e-3 -2.503e-3 -9.185e-3"/>
      		<mass value = "0.051725"/>
      		<inertia ixx = "0.001852"
               ixy = "0.00000"
               ixz="0.000153"
               iyy="0.003620"
               iyz="0.000000"
               izz="0.001951"/>
    	</inertial>
	</link>

	<joint name = "camera_support_to_camera" type = "fixed">
		<parent link = "camera_support_link" />
		<child link = "camera_link" />
		<origin xyz = "0.2 -0.35 0.35" rpy = "1.57 0 0"/>
	</joint>

	<!-- CAMERA-LINK -->
	<!-- Actual camera of the robot -->
	<link name = "camera_link">
		<visual>
			<origin xyz = "0 0 0" rpy = "1.57 0 1.57" />
			<geometry>
				<mesh filename = "package://cambot_description/meshes/cambot_camera.stl" />
			</geometry>
			<material name = "cambot/black">
				<color rgba = "0.0 0.0 0.0 1.0" />
			</material>
		</visual>
		<collision>
      		<origin xyz = "0 0 0" rpy = "1.57 0 1.57" />
      		<geometry>
        		<mesh filename = "package://cambot_description/meshes/cambot_camera_collision.stl" scale="0.01 0.01 0.01"/>
      		</geometry>
    	</collision>
		<inertial>
      		<origin rpy = "0 0 0" xyz = "7.035e-3 -70.134e-3 -87.744e-3"/>
      		<mass value = "0.0458425"/>
      		<inertia ixx = "0.001351"
               ixy = "0.000000"
               ixz="0.000000"
               iyy="0.000886"
               iyz="-0.000026"
               izz="0.001635"/>
    	</inertial>
	</link>
</robot>
