<!-- description of the robot -->
<robot name = "cambot">
	
	<!-- Robot -->
	
	<link name = "world" />
	
	<joint name = "cambot_world" type = "continuous">
		<parent link = "world" />
		<child link = "base_link" />
		<origin xyz = "0 0 0.5" rpy = "0 0 0"/>
		<axis xyz = "0 0 1" />
	</joint>
		
	<link name = "base_link">
		<visual>
			<origin xyz = "0 0 -0.5" rpy = "1.57 0 1.57" />
			<geometry>
				<mesh filename = "package://cambot_description/meshes/cambot.stl" />
			</geometry>
			<material name = "cambot/orange">
				<color rgba = "1.0 0.5 0.0 1.0" />
			</material>
		</visual>
	</link>

	<joint name = "base_to_camera" type = "continuous">
		<parent link = "base_link" />
		<child link = "camera_link" />
		<origin xyz = "0.3 -0.15 0.5" rpy = "-1.57 0 0" />
		<axis xyz = "0 0 1" />
		<safety_controller k_velocity="10" k_position="15" soft_lower_limit="-0.3" soft_upper_limit="0.5" />
	</joint>

	<link name = "camera_link">
		<visual>
			<origin xyz = "0 0 0" rpy = "0 -1.57 3.14" />
			<geometry>
				<mesh filename = "package://cambot_description/meshes/camera_conjunt.stl" />
			</geometry>
			<material name = "cambot/gray">
				<color rgba = "0.2 0.2 0.2 1.0" />
			</material>
		</visual>
	</link>
</robot>
